Workbook

Sheet Machine Details
A1: Machine 1
A2: Machine Name | B2: Surface Laptop 4
A3: Nominal CPU Speed (GHz), also the Nominal No. Of Instructions Per ns | B3: 3

Sheet VI Properties
A1: VI Properties
A2: Screenshot 1 | B2: The VI Properties of "NR" VIs
A24: Screenshot 2 | B24: The VI Properties of "SCR" VIs
A46: Screenshot 3 | B46: The VI Properties of "PCR" VIs

Sheet Exp1
B1: Experiment 1
B2: No. | C2: Time to run 1M calls of "Math SubVI - Simple (NR).vi" (seconds) | D2: Time to run 1M calls of "Math SubVI - Simple (SCR).vi" (seconds) | E2: Time to run 1M calls of "Math SubVI - Simple (PCR).vi" (seconds) | F2: Time to run 1M calls of "Math SubVI - Medium (NR).vi" (seconds) | G2: Time to run 1M calls of "Math SubVI - Medium (SCR).vi" (seconds) | H2: Time to run 1M calls of "Math SubVI - Medium (PCR).vi" (seconds) | I2: Time to run 1M calls of "Math SubVI - Complex (NR).vi" (seconds) | J2: Time to run 1M calls of "Math SubVI - Complex (SCR).vi" (seconds) | K2: Time to run 1M calls of "Math SubVI - Complex (PCR).vi" (seconds)
B3: 1 | C3: 0.05363 | D3: 0.052067 | E3: 0.027966 | F3: 0.120472 | G3: 0.107621 | H3: 0.110173 | I3: 0.782642 | J3: 0.814703 | K3: 0.768105
B4: 2 | C4: 0.0904 | D4: 0.054482 | E4: 0.020875 | F4: 0.121826 | G4: 0.108747 | H4: 0.083337 | I4: 0.817455 | J4: 0.786048 | K4: 0.75295
B5: 3 | C5: 0.058736 | D5: 0.053866 | E5: 0.032162 | F5: 0.134393 | G5: 0.106808 | H5: 0.146025 | I5: 0.785043 | J5: 0.787949 | K5: 0.781635
B6: 4 | C6: 0.056035 | D6: 0.054403 | E6: 0.026951 | F6: 0.138032 | G6: 0.108741 | H6: 0.086637 | I6: 0.783835 | J6: 0.845376 | K6: 0.750532
B7: 5 | C7: 0.057157 | D7: 0.053645 | E7: 0.020276 | F7: 0.137741 | G7: 0.108498 | H7: 0.090248 | I7: 0.783077 | J7: 0.785068 | K7: 0.760329
B8: 6 | C8: 0.050847 | D8: 0.052364 | E8: 0.021818 | F8: 0.128129 | G8: 0.120303 | H8: 0.134462 | I8: 0.833941 | J8: 0.785474 | K8: 0.759868
B9: 7 | C9: 0.053141 | D9: 0.054304 | E9: 0.023479 | F9: 0.168385 | G9: 0.111778 | H9: 0.087429 | I9: 0.790758 | J9: 0.792958 | K9: 0.791074
B10: 8 | C10: 0.055818 | D10: 0.061379 | E10: 0.02795 | F10: 0.252837 | G10: 0.114591 | H10: 0.089299 | I10: 0.780814 | J10: 0.786026 | K10: 0.75154
B11: 9 | C11: 0.053525 | D11: 0.053748 | E11: 0.02471 | F11: 0.190444 | G11: 0.119326 | H11: 0.093815 | I11: 0.782988 | J11: 0.790953 | K11: 0.762319
B12: 10 | C12: 0.057098 | D12: 0.054015 | E12: 0.02436 | F12: 0.122536 | G12: 0.116752 | H12: 0.084032 | I12: 0.787366 | J12: 0.787082 | K12: 0.784928
B13: 11 | C13: 0.057045 | D13: 0.073749 | E13: 0.048533 | F13: 0.118251 | G13: 0.107136 | H13: 0.080665 | I13: 0.788686 | J13: 0.814034 | K13: 0.755202
B14: 12 | C14: 0.056579 | D14: 0.053576 | E14: 0.020373 | F14: 0.132793 | G14: 0.109803 | H14: 0.093465 | I14: 0.792781 | J14: 0.787 | K14: 0.753296
... B17: 15 | C17: 0.051221 | D17: 0.053317 | E17: 0.02053 | F17: 0.153009 | G17: 0.112756 | H17: 0.099595 | I17: 0.788432 | J17: 0.815531 | K17: 0.784845
A18: Avg (seconds per 1M calls) | C18: =AVERAGE(Table145[Time to run 1M calls of "Math SubVI - Simple (NR).vi" (seconds)]) -> 0.059681267 | D18: =AVERAGE(Table145[Time to run 1M calls of "Math SubVI - Simple (SCR).vi" (seconds)]) -> 0.055431133 | E18: =AVERAGE(Table145[Time to run 1M calls of "Math SubVI - Simple (PCR).vi" (seconds)]) -> 0.025740733 | F18: =AVERAGE(Table145[Time to run 1M calls of "Math SubVI - Medium (NR).vi" (seconds)]) -> 0.14562627 | G18: =AVERAGE(Table145[Time to run 1M calls of "Math SubVI - Medium (SCR).vi" (seconds)]) -> 0.1126436 | H18: =AVERAGE(Table145[Time to run 1M calls of "Math SubVI - Medium (PCR).vi" (seconds)]) -> 0.099460467 | I18: =AVERAGE(Table145[Time to run 1M calls of "Math SubVI - Complex (NR).vi" (seconds)]) -> 0.7922758 | J18: =AVERAGE(Table145[Time to run 1M calls of "Math SubVI - Complex (SCR).vi" (seconds)]) -> 0.797061 | K18: =AVERAGE(Table145[Time to run 1M calls of "Math SubVI - Complex (PCR).vi" (seconds)]) -> 0.76515173
A19: Avg (us per call) | C19: =C18*1000000/1000000 -> 0.059681267 | D19: =D18*1000000/1000000 -> 0.055431133 | E19: =E18*1000000/1000000 -> 0.025740733 | F19: =F18*1000000/1000000 -> 0.14562627 | G19: =G18*1000000/1000000 -> 0.1126436 | H19: =H18*1000000/1000000 -> 0.099460467 | I19: =I18*1000000/1000000 -> 0.7922758 | J19: =J18*1000000/1000000 -> 0.797061 | K19: =K18*1000000/1000000 -> 0.76515173
A20: Difference (SCR/PCR - NR) (us per call) | C20: N/A | D20: =D19-C19 -> -0.0042501333 | E20: =E19-C19 -> -0.033940533 | F20: N/A | G20: =G19-F19 -> -0.032982667 | H20: =H19-F19 -> -0.0461658 | I20: N/A | J20: =J19-I19 -> 0.0047852 | K20: =K19-I19 -> -0.027124067
A21: Difference (SCR/PCR - NR) (ns per call) | C21: N/A | D21: =D20*1000 -> -4.2501333 | E21: =E20*1000 -> -33.940533 | F21: N/A | G21: =G20*1000 -> -32.982667 | H21: =H20*1000 -> -46.1658 | I21: N/A | J21: =J20*1000 -> 4.7852 | K21: =K20*1000 -> -27.124067
A22: Estimated No. of Instructions Per VI Call | C22: =C19*1000*'Machine Details'!$B$3 -> 179.0438 | D22: =D19*1000*'Machine Details'!$B$3 -> 166.2934 | E22: =E19*1000*'Machine Details'!$B$3 -> 77.2222 | F22: =F19*1000*'Machine Details'!$B$3 -> 436.8788 | G22: =G19*1000*'Machine Details'!$B$3 -> 337.9308 | H22: =H19*1000*'Machine Details'!$B$3 -> 298.3814 | I22: =I19*1000*'Machine Details'!$B$3 -> 2376.8274 | J22: =J19*1000*'Machine Details'!$B$3 -> 2391.183 | K22: =K19*1000*'Machine Details'!$B$3 -> 2295.4552
A23: No. of CPU Instructions Saved Per VI Call | C23: N/A | D23: =ROUND($C$22,0)-ROUND(D22,0) -> 13 | E23: =ROUND($C$22,0)-ROUND(E22,0) -> 102 | F23: N/A | G23: =ROUND($F$22,0)-ROUND(G22,0) -> 99 | H23: =ROUND($F$22,0)-ROUND(H22,0) -> 139 | I23: N/A | J23: =ROUND($I$22,0)-ROUND(J22,0) -> -14 | K23: =ROUND($I$22,0)-ROUND(K22,0) -> 82
A24: CPU Instructions Saved Per VI Call (percent) | C24: N/A | D24: =D23/$C$22 -> 0.072607932 | E24: =E23/$C$22 -> 0.569693 | F24: N/A | G24: =G23/$F$22 -> 0.22660747 | H24: =H23/$F$22 -> 0.31816605 | I24: N/A | J24: =J23/$I$22 -> -0.0058902047 | K24: =K23/$I$22 -> 0.034499771

Sheet Exp2
B1: Experiment 2
B2: No. | C2: Time to run 1M calls of "Math SubVI - Simple (NR).vi" (seconds) | D2: Time to run 1M calls of "Math SubVI - Simple (SCR).vi" (seconds) | E2: Time to run 1M calls of "Math SubVI - Simple (PCR).vi" (seconds) | F2: Time to run 1M calls of "Math SubVI - Medium (NR).vi" (seconds) | G2: Time to run 1M calls of "Math SubVI - Medium (SCR).vi" (seconds) | H2: Time to run 1M calls of "Math SubVI - Medium (PCR).vi" (seconds) | I2: Time to run 1M calls of "Math SubVI - Complex (NR).vi" (seconds) | J2: Time to run 1M calls of "Math SubVI - Complex (SCR).vi" (seconds) | K2: Time to run 1M calls of "Math SubVI - Complex (PCR).vi" (seconds)
B3: 1 | C3: 0.061002 | D3: 0.069387 | E3: 0.029143 | F3: 0.138246 | G3: 0.127764 | H3: 0.097702 | I3: 0.788093 | J3: 0.800677 | K3: 0.765096
B4: 2 | C4: 0.066146 | D4: 0.088253 | E4: 0.03095 | F4: 0.141753 | G4: 0.127016 | H4: 0.099673 | I4: 0.815433 | J4: 0.825641 | K4: 0.763316
B5: 3 | C5: 0.062734 | D5: 0.071449 | E5: 0.032685 | F5: 0.134289 | G5: 0.159872 | H5: 0.104267 | I5: 0.815216 | J5: 0.797166 | K5: 0.759996
B6: 4 | C6: 0.063042 | D6: 0.071496 | E6: 0.033625 | F6: 0.128429 | G6: 0.128277 | H6: 0.098386 | I6: 0.815535 | J6: 0.799825 | K6: 0.762578
B7: 5 | C7: 0.078125 | D7: 0.070885 | E7: 0.031021 | F7: 0.158691 | G7: 0.131726 | H7: 0.102519 | I7: 0.795484 | J7: 0.805878 | K7: 0.764596
B8: 6 | C8: 0.107928 | D8: 0.070861 | E8: 0.029322 | F8: 0.133421 | G8: 0.125542 | H8: 0.097639 | I8: 0.797536 | J8: 0.815079 | K8: 0.761994
B9: 7 | C9: 0.065849 | D9: 0.067902 | E9: 0.029758 | F9: 0.134923 | G9: 0.125357 | H9: 0.099663 | I9: 0.821585 | J9: 0.802909 | K9: 0.767192
B10: 8 | C10: 0.063151 | D10: 0.066947 | E10: 0.030334 | F10: 0.133324 | G10: 0.130029 | H10: 0.097924 | I10: 0.795 | J10: 0.805482 | K10: 0.759286
B11: 9 | C11: 0.063019 | D11: 0.109608 | E11: 0.039293 | F11: 0.131751 | G11: 0.124663 | H11: 0.098561 | I11: 0.79854 | J11: 0.804516 | K11: 0.764693
B12: 10 | C12: 0.062913 | D12: 0.065314 | E12: 0.031245 | F12: 0.131721 | G12: 0.138773 | H12: 0.100548 | I12: 0.797407 | J12: 0.808384 | K12: 0.762331
B13: 11 | C13: 0.06097 | D13: 0.070967 | E13: 0.031984 | F13: 0.152674 | G13: 0.131208 | H13: 0.09812 | I13: 0.801669 | J13: 0.801782 | K13: 0.779358
B14: 12 | C14: 0.068008 | D14: 0.071319 | E14: 0.02995 | F14: 0.157989 | G14: 0.124488 | H14: 0.095987 | I14: 0.793329 | J14: 0.828056 | K14: 0.767088
... B17: 15 | C17: 0.061259 | D17: 0.069202 | E17: 0.031108 | F17: 0.143338 | G17: 0.124508 | H17: 0.100184 | I17: 0.816954 | J17: 0.802619 | K17: 0.76862
A18: Avg (seconds per 1M calls) | C18: =AVERAGE(Table1456[Time to run 1M calls of "Math SubVI - Simple (NR).vi" (seconds)]) -> 0.068867333 | D18: =AVERAGE(Table1456[Time to run 1M calls of "Math SubVI - Simple (SCR).vi" (seconds)]) -> 0.0730372 | E18: =AVERAGE(Table1456[Time to run 1M calls of "Math SubVI - Simple (PCR).vi" (seconds)]) -> 0.031754467 | F18: =AVERAGE(Table1456[Time to run 1M calls of "Math SubVI - Medium (NR).vi" (seconds)]) -> 0.1461822 | G18: =AVERAGE(Table1456[Time to run 1M calls of "Math SubVI - Medium (SCR).vi" (seconds)]) -> 0.13046567 | H18: =AVERAGE(Table1456[Time to run 1M calls of "Math SubVI - Medium (PCR).vi" (seconds)]) -> 0.098935667 | I18: =AVERAGE(Table1456[Time to run 1M calls of "Math SubVI - Complex (NR).vi" (seconds)]) -> 0.8033736 | J18: =AVERAGE(Table1456[Time to run 1M calls of "Math SubVI - Complex (SCR).vi" (seconds)]) -> 0.80822627 | K18: =AVERAGE(Table1456[Time to run 1M calls of "Math SubVI - Complex (PCR).vi" (seconds)]) -> 0.76565493
A19: Avg (us per call) | C19: =C18*1000000/1000000 -> 0.068867333 | D19: =D18*1000000/1000000 -> 0.0730372 | E19: =E18*1000000/1000000 -> 0.031754467 | F19: =F18*1000000/1000000 -> 0.1461822 | G19: =G18*1000000/1000000 -> 0.13046567 | H19: =H18*1000000/1000000 -> 0.098935667 | I19: =I18*1000000/1000000 -> 0.8033736 | J19: =J18*1000000/1000000 -> 0.80822627 | K19: =K18*1000000/1000000 -> 0.76565493
A20: Difference (SCR/PCR - NR) (us per call) | C20: N/A | D20: =D19-C19 -> 0.0041698667 | E20: =E19-C19 -> -0.037112867 | F20: N/A | G20: =G19-F19 -> -0.015716533 | H20: =H19-F19 -> -0.047246533 | I20: N/A | J20: =J19-I19 -> 0.0048526667 | K20: =K19-I19 -> -0.037718667
A21: Difference (SCR/PCR - NR) (ns per call) | C21: N/A | D21: =D20*1000 -> 4.1698667 | E21: =E20*1000 -> -37.112867 | F21: N/A | G21: =G20*1000 -> -15.716533 | H21: =H20*1000 -> -47.246533 | I21: N/A | J21: =J20*1000 -> 4.8526667 | K21: =K20*1000 -> -37.718667
A22: Estimated No. of Instructions Per VI Call | C22: =C19*1000*'Machine Details'!$B$3 -> 206.602 | D22: =D19*1000*'Machine Details'!$B$3 -> 219.1116 | E22: =E19*1000*'Machine Details'!$B$3 -> 95.2634 | F22: =F19*1000*'Machine Details'!$B$3 -> 438.5466 | G22: =G19*1000*'Machine Details'!$B$3 -> 391.397 | H22: =H19*1000*'Machine Details'!$B$3 -> 296.807 | I22: =I19*1000*'Machine Details'!$B$3 -> 2410.1208 | J22: =J19*1000*'Machine Details'!$B$3 -> 2424.6788 | K22: =K19*1000*'Machine Details'!$B$3 -> 2296.9648
A23: No. of CPU Instructions Saved Per VI Call | C23: N/A | D23: =ROUND($C$22,0)-ROUND(D22,0) -> -12 | E23: =ROUND($C$22,0)-ROUND(E22,0) -> 112 | F23: N/A | G23: =ROUND($F$22,0)-ROUND(G22,0) -> 48 | H23: =ROUND($F$22,0)-ROUND(H22,0) -> 142 | I23: N/A | J23: =ROUND($I$22,0)-ROUND(J22,0) -> -15 | K23: =ROUND($I$22,0)-ROUND(K22,0) -> 113
A24: CPU Instructions Saved Per VI Call (percent) | C24: N/A | D24: =D23/$C$22 -> -0.05808269 | E24: =E23/$C$22 -> 0.54210511 | F24: N/A | G24: =G23/$F$22 -> 0.10945245 | H24: =H23/$F$22 -> 0.32379683 | I24: N/A | J24: =J23/$I$22 -> -0.0062237544 | K24: =K23/$I$22 -> 0.046885617

Sheet Exp3
B1: Experiment 3
B2: No. | C2: Time to run 1M calls of NR VIs (chain of Simple and Medium) (seconds) | D2: Time to run 1M calls of SCR VIs (chain of Simple and Medium) (seconds) | E2: Time to run 1M calls of PCR VIs (chain of Simple and Medium) (seconds)
B3: 1 | C3: 0.165297 | D3: 0.168068 | E3: 0.106174
B4: 2 | C4: 0.164036 | D4: 0.167556 | E4: 0.1008
B5: 3 | C5: 0.165414 | D5: 0.170594 | E5: 0.121519
B6: 4 | C6: 0.162572 | D6: 0.158585 | E6: 0.104128
B7: 5 | C7: 0.168884 | D7: 0.170505 | E7: 0.112242
B8: 6 | C8: 0.168551 | D8: 0.163944 | E8: 0.115022
B9: 7 | C9: 0.162983 | D9: 0.16539 | E9: 0.104787
B10: 8 | C10: 0.161833 | D10: 0.167253 | E10: 0.105076
B11: 9 | C11: 0.162678 | D11: 0.16338 | E11: 0.110259
B12: 10 | C12: 0.167482 | D12: 0.15972 | E12: 0.132519
B13: 11 | C13: 0.165517 | D13: 0.170462 | E13: 0.109622
B14: 12 | C14: 0.164482 | D14: 0.161446 | E14: 0.11252
... B17: 15 | C17: 0.162532 | D17: 0.166774 | E17: 0.102698
A18: Avg (seconds per 1M iterations) | C18: =AVERAGE(Table14567[Time to run 1M calls of NR VIs (chain of Simple and Medium) (seconds)]) -> 0.16688853 | D18: =AVERAGE(Table14567[Time to run 1M calls of SCR VIs (chain of Simple and Medium) (seconds)]) -> 0.165211 | E18: =AVERAGE(Table14567[Time to run 1M calls of PCR VIs (chain of Simple and Medium) (seconds)]) -> 0.11317273
A19: Avg (us per iteration) | C19: =C18*1000000/1000000 -> 0.16688853 | D19: =D18*1000000/1000000 -> 0.165211 | E19: =E18*1000000/1000000 -> 0.11317273
A20: Difference (SCR/PCR - NR) (us per iteration) | C20: N/A | D20: =D19-C19 -> -0.0016775333 | E20: =E19-C19 -> -0.0537158 | F20: Predictions based on Experiment 2: A) Total number of CPU instructions per VI call: NR + NR = 207 + 439 = 646; SCR + SCR: 219 + 391 = 610; PCR + PCR: 95 + 297 = 392; B) No. of CPU instructions saved per VI call: NR + NR = N/A (reference); SCR + SCR = -12 + 48 = 36; PCR + PCR = 112 + 142 = 254;
A21: Difference (SCR/PCR - NR) (ns per iteration) | C21: N/A | D21: =D20*1000 -> -1.6775333 | E21: =E20*1000 -> -53.7158
A22: Estimated No. of Instructions Per Loop Iteration | C22: =C19*1000*'Machine Details'!$B$3 -> 500.6656 | D22: =D19*1000*'Machine Details'!$B$3 -> 495.633 | E22: =E19*1000*'Machine Details'!$B$3 -> 339.5182 | F22: 646 | G22: 610 | H22: 392
A23: No. of CPU Instructions Saved Per Loop Iteration | C23: N/A | D23: =ROUND($C$22,0)-ROUND(D22,0) -> 5 | E23: =ROUND($C$22,0)-ROUND(E22,0) -> 161 | F23: N/A | G23: 36 | H23: 254
A24: CPU Instructions Saved Per Loop Iteration (percent) | C24: N/A | D24: =D23/$C$22 -> 0.0099867057 | E24: =E23/$C$22 -> 0.32157192

Sheet Exp4
B1: Experiment 4
B2: No. | C2: Time to run 1M calls of NR VIs (seconds) | D2: Time to run 1M calls of SCR VIs (seconds) | E2: Time to run 1M calls of PCR VIs (seconds)
B3: 1 | C3: 0.821281 | D3: 0.820777 | E3: 0.722619
B4: 2 | C4: 0.825337 | D4: 0.822175 | E4: 0.723318
B5: 3 | C5: 0.852245 | D5: 0.82579 | E5: 0.720352
B6: 4 | C6: 0.851332 | D6: 0.820997 | E6: 0.747599
B7: 5 | C7: 0.823549 | D7: 0.862172 | E7: 0.761784
B8: 6 | C8: 0.826968 | D8: 0.87156 | E8: 0.720704
B9: 7 | C9: 0.82971 | D9: 0.816539 | E9: 0.728641
B10: 8 | C10: 0.823379 | D10: 0.859963 | E10: 0.743312
B11: 9 | C11: 0.826551 | D11: 0.870557 | E11: 0.718341
B12: 10 | C12: 0.865691 | D12: 0.81455 | E12: 0.722545
B13: 11 | C13: 0.834461 | D13: 0.820334 | E13: 0.723512
B14: 12 | C14: 0.827061 | D14: 0.819318 | E14: 0.729356
... B17: 15 | C17: 0.8641 | D17: 0.820361 | E17: 0.728314
A18: Avg (seconds per 1M iterations) | C18: =AVERAGE(Table145678[Time to run 1M calls of NR VIs (seconds)]) -> 0.83646807 | D18: =AVERAGE(Table145678[Time to run 1M calls of SCR VIs (seconds)]) -> 0.83669347 | E18: =AVERAGE(Table145678[Time to run 1M calls of PCR VIs (seconds)]) -> 0.72996247
A19: Avg (us per iteration) | C19: =C18*1000000/1000000 -> 0.83646807 | D19: =D18*1000000/1000000 -> 0.83669347 | E19: =E18*1000000/1000000 -> 0.72996247
A20: Difference (SCR/PCR - NR) (us per iteration) | C20: N/A | D20: =D19-C19 -> 0.0002254 | E20: =E19-C19 -> -0.1065056
A21: Difference (SCR/PCR - NR) (ns per iteration) | C21: N/A | D21: =D20*1000 -> 0.2254 | E21: =E20*1000 -> -106.5056
A22: Estimated No. of Instructions Per Loop Iteration | C22: =C19*1000*'Machine Details'!$B$3 -> 2509.4042 | D22: =D19*1000*'Machine Details'!$B$3 -> 2510.0804 | E22: =E19*1000*'Machine Details'!$B$3 -> 2189.8874
A23: No. of CPU Instructions Saved Per Loop Iteration | C23: N/A | D23: =ROUND($C$22,0)-ROUND(D22,0) -> -1 | E23: =ROUND($C$22,0)-ROUND(E22,0) -> 319
A24: CPU Instructions Saved Per Loop Iteration (percent) | C24: N/A | D24: =D23/$C$22 -> -0.00039850097 | E24: =E23/$C$22 -> 0.12712181

Sheet Exp5
B1: Experiment 5
B2: No. | C2: Time to run 1M calls of NR VIs (seconds) | D2: Time to run 1M calls of PCR VIs (seconds)
B3: 1 | C3: 4.08738 | D3: 3.551553
B4: 2 | C4: 4.210702 | D4: 3.66986
B5: 3 | C5: 4.080395 | D5: 3.709581
B6: 4 | C6: 4.241777 | D6: 3.855426
B7: 5 | C7: 4.257788 | D7: 3.919783
B8: 6 | C8: 4.208865 | D8: 3.675926
B9: 7 | C9: 4.238855 | D9: 3.647602
B10: 8 | C10: 4.230691 | D10: 3.730895
B11: 9 | C11: 4.244228 | D11: 3.676309
B12: 10 | C12: 4.263449 | D12: 3.662639
B13: 11 | C13: 4.225381 | D13: 3.863173
B14: 12 | C14: 4.343841 | D14: 3.934409
... B17: 15 | C17: 4.328922 | D17: 3.71876
A18: Avg (seconds per 1M iterations) | C18: =AVERAGE(Table1456789[Time to run 1M calls of NR VIs (seconds)]) -> 4.2399029 | D18: =AVERAGE(Table1456789[Time to run 1M calls of PCR VIs (seconds)]) -> 3.7495121
A19: Avg (us per iteration) | C19: =C18*1000000/1000000 -> 4.2399029 | D19: =D18*1000000/1000000 -> 3.7495121
A20: Difference (SCR/PCR - NR) (us per iteration) | C20: N/A | D20: =D19-C19 -> -0.49039087
A21: Difference (SCR/PCR - NR) (ns per iteration) | C21: N/A | D21: =D20*1000 -> -490.39087
A22: Estimated No. of Instructions Per Loop Iteration | C22: =C19*1000*'Machine Details'!$B$3 -> 12719.709 | D22: =D19*1000*'Machine Details'!$B$3 -> 11248.536
A23: No. of CPU Instructions Saved Per Loop Iteration | C23: N/A | D23: =ROUND($C$22,0)-ROUND(D22,0) -> 1471
A24: CPU Instructions Saved Per Loop Iteration (percent) | C24: N/A | D24: =D23/$C$22 -> 0.1156473

Sheet Exp6
B1: Experiment 6
B2: No. | C2: Time to run 1M calls of NR DBG OFF VIs (seconds) | D2: Time to run 1M calls of PCR DBG OFF VIs (seconds) | E2: Time to run 1M calls of PCR DBG OFF INLN VIs (seconds) | F2: Time to run 1M calls of PCR SBRTN VIs (seconds)
B3: 1 | C3: 3.96038 | D3: 3.4778 | E3: 3.605138 | F3: 3.690511
B4: 2 | C4: 4.275892 | D4: 3.766719 | E4: 3.729604 | F4: 3.61651
B5: 3 | C5: 4.038403 | D5: 3.796842 | E5: 3.541173 | F5: 4.104378
B6: 4 | C6: 4.107834 | D6: 3.857872 | E6: 3.984263 | F6: 3.477472
B7: 5 | C7: 4.674286 | D7: 3.744022 | E7: 3.615348 | F7: 3.668778
B8: 6 | C8: 4.490007 | D8: 3.526475 | E8: 3.487181 | F8: 3.910332
B9: 7 | C9: 4.012537 | D9: 3.653177 | E9: 3.48637 | F9: 3.650847
B10: 8 | C10: 4.223145 | D10: 4.052267 | E10: 3.577834 | F10: 3.854219
B11: 9 | C11: 4.178258 | D11: 3.714462 | E11: 3.688306 | F11: 3.784613
B12: 10 | C12: 4.254147 | D12: 3.637799 | E12: 3.511616 | F12: 3.655502
A13: Avg (seconds per 1M iterations) | C13: =AVERAGE(Table145678910[Time to run 1M calls of NR DBG OFF VIs (seconds)]) -> 4.2214889 | D13: =AVERAGE(Table145678910[Time to run 1M calls of PCR DBG OFF VIs (seconds)]) -> 3.7227435 | E13: =AVERAGE(Table145678910[Time to run 1M calls of PCR DBG OFF INLN VIs (seconds)]) -> 3.6226833 | F13: =AVERAGE(Table145678910[Time to run 1M calls of PCR SBRTN VIs (seconds)]) -> 3.7413162 | H13: From Experiment 5 ("Allow debugging" On)
A14: Avg (us per iteration) | C14: =C13*1000000/1000000 -> 4.2214889 | D14: =D13*1000000/1000000 -> 3.7227435 | E14: =E13*1000000/1000000 -> 3.6226833 | F14: =F13*1000000/1000000 -> 3.7413162 | H14: 4.2399029 | I14: 3.7495121 | J14: Effect of turning Inline on for PCR VIs | L14: Effect of turning Subroutine on for PCR VIs
A15: Difference (SCR/PCR - NR) (us per iteration) | C15: N/A | D15: =D14-C14 -> -0.4987454 | G15: Reduction when DBG OFF (us) | H15: =H14-C14 -> 0.018414033 | I15: =I14-D14 -> 0.026768567 | J15: Reduction (us) | K15: =D14-E14 -> 0.1000602 | L15: TBD. Slight performance decrease. To be repeated.
A16: Difference (SCR/PCR - NR) (ns per iteration) | C16: N/A | D16: =D15*1000 -> -498.7454 | G16: Reduction when DBG OFF (%) | H16: =H15/H14 -> 0.0043430318 | I16: =I15/I14 -> 0.0071392134 | J16: Reduction (%) | K16: =K15/D14 -> 0.026878081
A17: Estimated No. of Instructions Per Loop Iteration | C17: =C14*1000*'Machine Details'!$B$3 -> 12664.467 | D17: =D14*1000*'Machine Details'!$B$3 -> 11168.23
A18: No. of CPU Instructions Saved Per Loop Iteration | C18: N/A | D18: =ROUND($C$17,0)-ROUND(D17,0) -> 1496
A19: CPU Instructions Saved Per Loop Iteration (percent) | C19: N/A | D19: =D18/$C$17 -> 0.11812578

Sheet Exp6 (rerun)
B1: Experiment 6
B2: No. | C2: Time to run 1M calls of NR DBG OFF VIs (seconds) | D2: Time to run 1M calls of PCR DBG OFF VIs (seconds) | E2: Time to run 1M calls of PCR DBG OFF INLN VIs (seconds) | F2: Time to run 1M calls of PCR SBRTN VIs (seconds)
B3: 1 | C3: 4.095768 | D3: 3.920875 | E3: 3.69789 | F3: 3.590918
B4: 2 | C4: 4.494904 | D4: 3.597574 | E4: 3.380239 | F4: 3.648729
B5: 3 | C5: 4.13228 | D5: 3.908174 | E5: 3.342775 | F5: 3.657111
B6: 4 | C6: 4.333219 | D6: 4.009088 | E6: 3.43557 | F6: 3.665399
B7: 5 | C7: 4.350203 | D7: 3.634688 | E7: 3.655576 | F7: 3.59619
B8: 6 | C8: 4.11473 | D8: 3.58799 | E8: 3.378638 | F8: 3.629749
B9: 7 | C9: 4.134786 | D9: 3.594828 | E9: 3.810212 | F9: 4.018614
B10: 8 | C10: 4.153629 | D10: 3.5584 | E10: 3.616552 | F10: 3.642988
B11: 9 | C11: 4.179788 | D11: 3.918883 | E11: 3.618999 | F11: 3.647603
B12: 10 | C12: 4.139433 | D12: 3.809839 | E12: 3.436042 | F12: 3.853759
A13: Avg (seconds per 1M iterations) | C13: =AVERAGE(Table1456789102[Time to run 1M calls of NR DBG OFF VIs (seconds)]) -> 4.212874 | D13: =AVERAGE(Table1456789102[Time to run 1M calls of PCR DBG OFF VIs (seconds)]) -> 3.7540339 | E13: =AVERAGE(Table1456789102[Time to run 1M calls of PCR DBG OFF INLN VIs (seconds)]) -> 3.5372493 | F13: =AVERAGE(Table1456789102[Time to run 1M calls of PCR SBRTN VIs (seconds)]) -> 3.695106 | H13: From Experiment 5 ("Allow debugging" On)
A14: Avg (us per iteration) | C14: =C13*1000000/1000000 -> 4.212874 | D14: =D13*1000000/1000000 -> 3.7540339 | E14: =E13*1000000/1000000 -> 3.5372493 | F14: =F13*1000000/1000000 -> 3.695106 | H14: 4.2399029 | I14: 3.7495121 | J14: Effect of turning Inline on for PCR VIs | L14: Effect of turning Subroutine on for PCR VIs
A15: Difference (SCR/PCR - NR) (us per iteration) | C15: N/A | D15: =D14-C14 -> -0.4588401 | G15: Reduction when DBG OFF (us) | H15: =H14-C14 -> 0.027028933 | I15: =I14-D14 -> -0.0045218333 | J15: Reduction (us) | K15: =D14-E14 -> 0.2167846 | L15: Reduction (us) | M15: =D14-F14 -> 0.0589279
A16: Difference (SCR/PCR - NR) (ns per iteration) | C16: N/A | D16: =D15*1000 -> -458.8401 | G16: Reduction when DBG OFF (%) | H16: =H15/H14 -> 0.0063748944 | I16: =I15/I14 -> -0.0012059791 | J16: Reduction (%) | K16: =K15/D14 -> 0.057747108 | L16: Reduction (%) | M16: =M15/D14 -> 0.015697221
A17: Estimated No. of Instructions Per Loop Iteration | C17: =C14*1000*'Machine Details'!$B$3 -> 12638.622 | D17: =D14*1000*'Machine Details'!$B$3 -> 11262.102 | L17: Subroutine is less performant than inline by this much | M17: =(E14-F14)/E14 -> -0.044626965
A18: No. of CPU Instructions Saved Per Loop Iteration | C18: N/A | D18: =ROUND($C$17,0)-ROUND(D17,0) -> 1377
A19: CPU Instructions Saved Per Loop Iteration (percent) | C19: N/A | D19: =D18/$C$17 -> 0.10895175

Sheet Exp7
B1: Experiment 7
B2: No. | C2: No. Of Iterations Executed - NR VIs - One Loop | D2: No. Of Iterations Executed - NR VIs - Two Loops | E2: No. Of Iterations Executed - NR VIs - Four Loops | F2: No. Of Iterations Executed - SCR VIs - One Loop | G2: No. Of Iterations Executed - SCR VIs - Two Loops | H2: No. Of Iterations Executed - SCR VIs - Four Loops | I2: No. Of Iterations Executed - PCR VIs - One Loop | J2: No. Of Iterations Executed - PCR VIs - Two Loops | K2: No. Of Iterations Executed - PCR VIs - Four Loops | L2: No. Of Iterations Executed - PCR + SBRTN VIs - One Loop | M2: No. Of Iterations Executed - PCR + SBRTN VIs - Two Loops | N2: No. Of Iterations Executed - PCR + SBRTN VIs - Four Loops | O2: No. Of Iterations Executed - PCR + INLN VIs - One Loop | P2: No. Of Iterations Executed - PCR + INLN VIs - Two Loops | Q2: No. Of Iterations Executed - PCR + INLN VIs - Four Loops
B3: 1 | C3: 2519512 | D3: 661961 | E3: 319940 | F3: 2489299 | G3: 1812673 | H3: 1291538 | I3: 2832228 | J3: 2786143.5 | K3: 2190395 | L3: 2920310 | M3: 2840622 | N3: 2560713.8 | O3: 3024636 | P3: 3046766.5 | Q3: 2767462
B4: 2 | C4: 2516594 | D4: 671589 | E4: 295073 | F4: 2453654 | G4: 1802718 | H4: 1313160.2 | I4: 2807671 | J4: 2545010.5 | K4: 2221798.5 | L4: 2750044 | M4: 2604215 | N4: 2562493.2 | O4: 2968258 | P4: 2917429 | Q4: 2766646.5
B5: 3 | C5: 2516594 | D5: 603573 | E5: 312654 | F5: 2494426 | G5: 1771046 | H5: 1347294.8 | I5: 2684938 | J5: 2435640 | K5: 2197518.5 | L5: 2618353 | M5: 2722852 | N5: 2565710.5 | O5: 3021813 | P5: 3006191.5 | Q5: 2775365.5
B6: 4 | C6: 2239771 | D6: 597038 | E6: 281858 | F6: 2241079 | G6: 1721480 | H6: 1300268 | I6: 2840643 | J6: 2503089.5 | K6: 2200997.5 | L6: 2818196 | M6: 2416324.5 | N6: 2544383 | O6: 3043026 | P6: 2962788 | Q6: 2786444.2
B7: 5 | C7: 2480680 | D7: 604739 | E7: 276390 | F7: 2397781 | G7: 1803361 | H7: 1342010 | I7: 2834223 | J7: 2581418.5 | K7: 2208522.8 | L7: 2892091 | M7: 2565614 | N7: 2574879 | O7: 3030470 | P7: 2877513.5 | Q7: 2761441.2
A8: Avg no. of iterations | C8: =AVERAGE(Table14567891023[No. Of Iterations Executed - NR VIs - One Loop]) -> 2454630.2 | D8: =AVERAGE(Table14567891023[No. Of Iterations Executed - NR VIs - Two Loops]) -> 627780 | E8: =AVERAGE(Table14567891023[No. Of Iterations Executed - NR VIs - Four Loops]) -> 297183 | F8: =AVERAGE(Table14567891023[No. Of Iterations Executed - SCR VIs - One Loop]) -> 2415247.8 | G8: =AVERAGE(Table14567891023[No. Of Iterations Executed - SCR VIs - Two Loops]) -> 1782255.6 | H8: =AVERAGE(Table14567891023[No. Of Iterations Executed - SCR VIs - Four Loops]) -> 1318854.2 | I8: =AVERAGE(Table14567891023[No. Of Iterations Executed - PCR VIs - One Loop]) -> 2799940.6 | J8: =AVERAGE(Table14567891023[No. Of Iterations Executed - PCR VIs - Two Loops]) -> 2570260.4 | K8: =AVERAGE(Table14567891023[No. Of Iterations Executed - PCR VIs - Four Loops]) -> 2203846.5 | L8: =AVERAGE(Table14567891023[No. Of Iterations Executed - PCR + SBRTN VIs - One Loop]) -> 2799798.8 | M8: =AVERAGE(Table14567891023[No. Of Iterations Executed - PCR + SBRTN VIs - Two Loops]) -> 2629925.5 | N8: =AVERAGE(Table14567891023[No. Of Iterations Executed - PCR + SBRTN VIs - Four Loops]) -> 2561635.9 | O8: =AVERAGE(Table14567891023[No. Of Iterations Executed - PCR + INLN VIs - One Loop]) -> 3017640.6 | P8: =AVERAGE(Table14567891023[No. Of Iterations Executed - PCR + INLN VIs - Two Loops]) -> 2962137.7 | Q8: =AVERAGE(Table14567891023[No. Of Iterations Executed - PCR + INLN VIs - Four Loops]) -> 2771471.9
C9: NR VIs | F9: SCR VIs | I9: PCR VIs (DBG ON) | L9: PCR VIs (DBG OFF + Subroutine) | O9: PCR VIs (DBG OFF + Inline)
A11: Avg no. of iterations for NR VIs across 1, 2, 4 loops | C11: =AVERAGE(C8:E8) -> 1126531.1 | D11: N/A
A12: Avg no. of iterations for SCR VIs across 1, 2, 4 loops | C12: =AVERAGE(F8:H8) -> 1838785.9 | D12: =(C12/$C$11)-1 -> 0.63225491 | E12: =(C12/$C$11) -> 1.6322549 | F12: Performance increase w.r.t. NR
A13: Avg no. of iterations for PCR VIs DBG ON across 1, 2, 4 loops | C13: =AVERAGE(I8:K8) -> 2524682.5 | D13: =(C13/$C$11)-1 -> 1.2411122 | E13: =(C13/$C$11) -> 2.2411122
A14: Avg no. of iterations for PCR VIs Subroutine across 1, 2, 4 loops | C14: =AVERAGE(L8:N8) -> 2663786.7 | D14: =(C14/$C$11)-1 -> 1.3645923 | E14: =(C14/$C$11) -> 2.3645923
A15: Avg no. of iterations for PCR VIs Subroutine across 1, 2, 4 loops | C15: =AVERAGE(O8:Q8) -> 2917083.4 | D15: =(C15/$C$11)-1 -> 1.5894389 | E15: =(C15/$C$11) -> 2.5894389

Sheet Exp7 (rerun with C=10)
B1: Experiment 7 (rerun with Compiler setting set to 10 out of 10)
B2: No. | C2: No. Of Iterations Executed - PCR + SBRTN VIs - One Loop | D2: No. Of Iterations Executed - PCR + SBRTN VIs - Two Loops | E2: No. Of Iterations Executed - PCR + SBRTN VIs - Four Loops | F2: No. Of Iterations Executed - PCR + INLN VIs - One Loop | G2: No. Of Iterations Executed - PCR + INLN VIs - Two Loops | H2: No. Of Iterations Executed - PCR + INLN VIs - Four Loops | I2: No. Of Iterations Executed - PCR + SBRTN VIs - Four Loops (EXE) | J2: No. Of Iterations Executed - PCR + INLN VIs - Four Loops (EXE)
B3: 1 | C3: 2921522 | D3: 2899873.5 | E3: 2671050.5 | F3: 3059830 | G3: 3046711 | H3: 2761482.2 | I3: 2671435.8 | J3: 2807132.2
B4: 2 | C4: 2907960 | D4: 2907366.5 | E4: 2642273.2 | F4: 2989816 | G4: 3044733.5 | H4: 2863444 | I4: 2686580.8 | J4: 2851979.5
B5: 3 | C5: 2868757 | D5: 2811685 | E5: 2686058.8 | F5: 3073643 | G5: 2945875.5 | H5: 2839418.8 | I5: 2694690.2 | J5: 2805144.5
B6: 4 | C6: 2907656 | D6: 2856627.5 | E6: 2671002 | F6: 3069427 | G6: 3023293 | H6: 2820222.5 | I6: 2643428.5 | J6: 2833177.5
B7: 5 | C7: 2911904 | D7: 2883803.5 | E7: 2600095 | F7: 3044035 | G7: 3044111 | H7: 2817586 | I7: 2641206.8 | J7: 2855805.2
A8: Avg no. of iterations | C8: =AVERAGE(Table145678910234[No. Of Iterations Executed - PCR + SBRTN VIs - One Loop]) -> 2903559.8 | D8: =AVERAGE(Table145678910234[No. Of Iterations Executed - PCR + SBRTN VIs - Two Loops]) -> 2871871.2 | E8: =AVERAGE(Table145678910234[No. Of Iterations Executed - PCR + SBRTN VIs - Four Loops]) -> 2654095.9 | F8: =AVERAGE(Table145678910234[No. Of Iterations Executed - PCR + INLN VIs - One Loop]) -> 3047350.2 | G8: =AVERAGE(Table145678910234[No. Of Iterations Executed - PCR + INLN VIs - Two Loops]) -> 3020944.8 | H8: =AVERAGE(Table145678910234[No. Of Iterations Executed - PCR + INLN VIs - Four Loops]) -> 2820430.7 | I8: =AVERAGE(Table145678910234[No. Of Iterations Executed - PCR + SBRTN VIs - Four Loops (EXE)]) -> 2667468.4 | J8: =AVERAGE(Table145678910234[No. Of Iterations Executed - PCR + INLN VIs - Four Loops (EXE)]) -> 2830647.8
C9: PCR VIs (DBG OFF + Subroutine) | F9: PCR VIs (DBG OFF + Inline) | I9: PCR VIs (DBG OFF + Subroutine), EXE | J9: PCR VIs (DBG OFF + Inline), EXE
A10: Performance Increase of Inline w.r.t. Subroutine - One Loop - Dev Env (%) | C10: =(F8/C8)-1 -> 0.049522107
A11: Performance Increase of Inline w.r.t. Subroutine - Two Loops - Dev Env (%) | C11: =(G8/D8)-1 -> 0.051908177
A12: Performance Increase of Inline w.r.t. Subroutine - Four Loops - Dev Env (%) | C12: =(H8/E8)-1 -> 0.062670983
A13: Performance Increase of Inline w.r.t. Subroutine - Four Loops - EXE (%) | C13: =(J8/I8)-1 -> 0.061173868

Sheet Exp12-EXE File Size
B1: Experiment 12 - EXE File Size
B2: No. | C2: File Size of "Experiment 12.exe" when using subroutine VIs (bytes) | D2: File Size of "Experiment 12.exe" when using inline VIs (bytes)
B3: 1 | C3: 247808 | D3: 274432
B4: 2 | C4: 247808 | D4: 274432
B5: 3 | C5: 247808 | D5: 274432
A6: Avg EXE File Size (bytes) | C6: =AVERAGE(Table14567891023411[File Size of "Experiment 12.exe" when using subroutine VIs (bytes)]) -> 247808 | D6: =AVERAGE(Table14567891023411[File Size of "Experiment 12.exe" when using inline VIs (bytes)]) -> 274432
A7: Avg EXE File Size (KB) | C7: =C6/1024 -> 242 | D7: =D6/1024 -> 268
A8: Size Difference (bytes) | C8: N/A | D8: =D6-C6 -> 26624
A9: Size Difference (KB) | C9: N/A | D9: =D7-C7 -> 26
A10: Size Difference (%) | C10: N/A | D10: =D8/C6 -> 0.10743802
A11: No. Of SubVI Instances Per Loop | C11: 5
A12: No. Of Different SubVIs | C12: 3
A13: No. Of Loops | C13: 10
A14: Total Number Of SubVI Call Locations | C14: =C11*C12*C13 -> 150
A15: Size Difference Per Call Location (bytes per call location) | C15: =D8/C14 -> 177.49333

Sheet Exp12-Variability
B1: Experiment 12.vi with subroutine VIs (DDS "Case 1: Subroutines")
B2: No. | C2: No. Of Iterations Block Of Text - Run 1 | D2: No. Of Iterations Block Of Text - Run 2 | E2: No. Of Iterations Block Of Text - Run 3 | F2: No. Of Iterations Block Of Text - Run 4 | G2: No. Of Iterations Block Of Text - Run 5 | H2: No. Of Iterations Block Of Text - Run 6 | I2: No. Of Iterations Block Of Text - Run 7 | J2: No. Of Iterations Block Of Text - Run 8 | K2: No. Of Iterations Block Of Text - Run 9 | L2: No. Of Iterations Block Of Text - Run 10
B3: 1 | C3: 321034 | D3: 333909 | E3: 343149 | F3: 329195 | G3: 278295 | H3: 322368 | I3: 331302 | J3: 299830 | K3: 325419 | L3: 351392
B4: 2 | C4: 340260 | D4: 315211 | E4: 283497 | F4: 338195 | G4: 298388 | H4: 343964 | I4: 335369 | J4: 327230 | K4: 293451 | L4: 315213
B5: 3 | C5: 299273 | D5: 281798 | E5: 315728 | F5: 282783 | G5: 261704 | H5: 356843 | I5: 313580 | J5: 360615 | K5: 309086 | L5: 328574
B6: 4 | C6: 340869 | D6: 351502 | E6: 298030 | F6: 325886 | G6: 277348 | H6: 352658 | I6: 314572 | J6: 326317 | K6: 320964 | L6: 316550
B7: 5 | C7: 284746 | D7: 322565 | E7: 357978 | F7: 306215 | G7: 258985 | H7: 351251 | I7: 346493 | J7: 306214 | K7: 336371 | L7: 286490
B8: 6 | C8: 306618 | D8: 287592 | E8: 298008 | F8: 321659 | G8: 284977 | H8: 314006 | I8: 307891 | J8: 360111 | K8: 328778 | L8: 296003
B9: 7 | C9: 359847 | D9: 313521 | E9: 334240 | F9: 327935 | G9: 271104 | H9: 317131 | I9: 342668 | J9: 318223 | K9: 320994 | L9: 322622
B10: 8 | C10: 350140 | D10: 292169 | E10: 323991 | F10: 304954 | G10: 324144 | H10: 329597 | I10: 379275 | J10: 331406 | K10: 321068 | L10: 345853
B11: 9 | C11: 325490 | D11: 318528 | E11: 352810 | F11: 352060 | G11: 332786 | H11: 308099 | I11: 349039 | J11: 343918 | K11: 322589 | L11: 348974
B12: 10 | C12: 334493 | D12: 333276 | E12: 363937 | F12: 342661 | G12: 288420 | H12: 314528 | I12: 341067 | J12: 341548 | K12: 328782 | L12: 314765
A13: Avg No. Of Iterations | C13: =AVERAGE(Table1456789102341112[No. Of Iterations Block Of Text - Run 1]) -> 326277 | D13: =AVERAGE(Table1456789102341112[No. Of Iterations Block Of Text - Run 2]) -> 315007.1 | E13: =AVERAGE(Table1456789102341112[No. Of Iterations Block Of Text - Run 3]) -> 327136.8 | F13: =AVERAGE(Table1456789102341112[No. Of Iterations Block Of Text - Run 4]) -> 323154.3 | G13: =AVERAGE(Table1456789102341112[No. Of Iterations Block Of Text - Run 5]) -> 287615.1 | H13: =AVERAGE(Table1456789102341112[No. Of Iterations Block Of Text - Run 6]) -> 331044.5 | I13: =AVERAGE(Table1456789102341112[No. Of Iterations Block Of Text - Run 7]) -> 336125.6 | J13: =AVERAGE(Table1456789102341112[No. Of Iterations Block Of Text - Run 8]) -> 331541.2 | K13: =AVERAGE(Table1456789102341112[No. Of Iterations Block Of Text - Run 9]) -> 320750.2 | L13: =AVERAGE(Table1456789102341112[No. Of Iterations Block Of Text - Run 10]) -> 322643.6
A14: Min No. Of Iterations | C14: =MIN(Table1456789102341112[No. Of Iterations Block Of Text - Run 1]) -> 284746 | D14: =MIN(Table1456789102341112[No. Of Iterations Block Of Text - Run 2]) -> 281798 | E14: =MIN(Table1456789102341112[No. Of Iterations Block Of Text - Run 3]) -> 283497 | F14: =MIN(Table1456789102341112[No. Of Iterations Block Of Text - Run 4]) -> 282783 | G14: =MIN(Table1456789102341112[No. Of Iterations Block Of Text - Run 5]) -> 258985 | H14: =MIN(Table1456789102341112[No. Of Iterations Block Of Text - Run 6]) -> 308099 | I14: =MIN(Table1456789102341112[No. Of Iterations Block Of Text - Run 7]) -> 307891 | J14: =MIN(Table1456789102341112[No. Of Iterations Block Of Text - Run 8]) -> 299830 | K14: =MIN(Table1456789102341112[No. Of Iterations Block Of Text - Run 9]) -> 293451 | L14: =MIN(Table1456789102341112[No. Of Iterations Block Of Text - Run 10]) -> 286490
A15: Max No. Of Iterations | C15: =MAX(Table1456789102341112[No. Of Iterations Block Of Text - Run 1]) -> 359847 | D15: =MAX(Table1456789102341112[No. Of Iterations Block Of Text - Run 2]) -> 351502 | E15: =MAX(Table1456789102341112[No. Of Iterations Block Of Text - Run 3]) -> 363937 | F15: =MAX(Table1456789102341112[No. Of Iterations Block Of Text - Run 4]) -> 352060 | G15: =MAX(Table1456789102341112[No. Of Iterations Block Of Text - Run 5]) -> 332786 | H15: =MAX(Table1456789102341112[No. Of Iterations Block Of Text - Run 6]) -> 356843 | I15: =MAX(Table1456789102341112[No. Of Iterations Block Of Text - Run 7]) -> 379275 | J15: =MAX(Table1456789102341112[No. Of Iterations Block Of Text - Run 8]) -> 360615 | K15: =MAX(Table1456789102341112[No. Of Iterations Block Of Text - Run 9]) -> 336371 | L15: =MAX(Table1456789102341112[No. Of Iterations Block Of Text - Run 10]) -> 351392
A16: Range (Max - Min) | C16: =C15-C14 -> 75101 | D16: =D15-D14 -> 69704 | E16: =E15-E14 -> 80440 | F16: =F15-F14 -> 69277 | G16: =G15-G14 -> 73801 | H16: =H15-H14 -> 48744 | I16: =I15-I14 -> 71384 | J16: =J15-J14 -> 60785 | ... L16: =L15-L14 -> 64902
A17: Range (percentage of Min) | C17: =C16/C14 -> 0.26374734 | D17: =D16/D14 -> 0.24735449 | E17: =E16/E14 -> 0.28374198 | F17: =F16/F14 -> 0.2449829 | G17: =G16/G14 -> 0.28496245 | H17: =H16/H14 -> 0.15820889 | I17: =I16/I14 -> 0.23184828 | J17: =J16/J14 -> 0.20273155 | ... L17: =L16/L14 -> 0.22654194
A18: Smallest Range (Tightest Execution) (%) | C18: =MIN(C17:L17) -> 0.14625951
A19: Largest Range (Loosest Execution) (%) | C19: =MAX(C17:L17) -> 0.28496245
A20: Average Range (%) | C20: =AVERAGE(C17:L17) -> 0.22903793
A21: Overall Average No. Of Iterations | C21: =AVERAGE(C13:L13) -> 322129.54
B23: Experiment 12.vi with inline VIs (DDS "Case 2: Inline VIs")
B24: No. | C24: No. Of Iterations Block Of Text - Run 1 | D24: No. Of Iterations Block Of Text - Run 2 | E24: No. Of Iterations Block Of Text - Run 3 | F24: No. Of Iterations Block Of Text - Run 4 | G24: No. Of Iterations Block Of Text - Run 5 | H24: No. Of Iterations Block Of Text - Run 6 | I24: No. Of Iterations Block Of Text - Run 7 | J24: No. Of Iterations Block Of Text - Run 8 | K24: No. Of Iterations Block Of Text - Run 9 | L24: No. Of Iterations Block Of Text - Run 10
B25: 1 | C25: 346198 | D25: 350676 | E25: 368058 | F25: 368692 | G25: 310634 | H25: 350036 | I25: 340453 | J25: 334691 | K25: 329256 | L25: 346833
B26: 2 | C26: 358183 | D26: 368940 | E26: 341577 | F26: 326910 | G26: 384460 | H26: 355559 | I26: 287918 | J26: 316965 | K26: 351950 | L26: 357143
B27: 3 | C27: 362710 | D27: 343214 | E27: 341189 | F27: 325675 | G27: 341051 | H27: 330557 | I27: 355159 | J27: 354602 | K27: 352898 | L27: 347299
B28: 4 | C28: 352338 | D28: 358751 | E28: 371419 | F28: 336583 | G28: 353230 | H28: 365816 | I28: 353083 | J28: 328661 | K28: 356582 | L28: 358697
B29: 5 | C29: 338940 | D29: 388675 | E29: 389228 | F29: 349658 | G29: 351159 | H29: 362532 | I29: 363668 | J29: 363108 | K29: 384589 | L29: 360046
B30: 6 | C30: 308097 | D30: 351028 | E30: 356922 | F30: 333545 | G30: 365832 | H30: 381199 | I30: 358274 | J30: 366776 | K30: 370955 | L30: 381612
B31: 7 | C31: 333316 | D31: 352568 | E31: 390909 | F31: 370125 | G31: 372786 | H31: 359096 | I31: 372895 | J31: 357183 | K31: 355098 | L31: 329225
B32: 8 | C32: 360032 | D32: 365103 | E32: 377851 | F32: 389873 | G32: 370531 | H32: 327544 | I32: 356351 | J32: 379764 | K32: 332880 | L32: 368757
B33: 9 | C33: 358505 | D33: 314058 | E33: 283908 | F33: 340132 | G33: 347979 | H33: 361870 | I33: 355064 | J33: 330701 | K33: 343305 | L33: 336417
B34: 10 | C34: 385768 | D34: 378125 | E34: 383860 | F34: 364563 | G34: 334262 | H34: 358600 | I34: 372372 | J34: 371570 | K34: 282415 | L34: 322104
A35: Avg No. Of Iterations | C35: =AVERAGE(Table145678910234111213[No. Of Iterations Block Of Text - Run 1]) -> 350408.7 | D35: =AVERAGE(Table145678910234111213[No. Of Iterations Block Of Text - Run 2]) -> 357113.8 | E35: =AVERAGE(Table145678910234111213[No. Of Iterations Block Of Text - Run 3]) -> 360492.1 | F35: =AVERAGE(Table145678910234111213[No. Of Iterations Block Of Text - Run 4]) -> 350575.6 | G35: =AVERAGE(Table145678910234111213[No. Of Iterations Block Of Text - Run 5]) -> 353192.4 | H35: =AVERAGE(Table145678910234111213[No. Of Iterations Block Of Text - Run 6]) -> 355280.9 | I35: =AVERAGE(Table145678910234111213[No. Of Iterations Block Of Text - Run 7]) -> 351523.7 | J35: =AVERAGE(Table145678910234111213[No. Of Iterations Block Of Text - Run 8]) -> 350402.1 | K35: =AVERAGE(Table145678910234111213[No. Of Iterations Block Of Text - Run 9]) -> 345992.8 | L35: =AVERAGE(Table145678910234111213[No. Of Iterations Block Of Text - Run 10]) -> 350813.3
A36: Min No. Of Iterations | C36: =MIN(Table145678910234111213[No. Of Iterations Block Of Text - Run 1]) -> 308097 | D36: =MIN(Table145678910234111213[No. Of Iterations Block Of Text - Run 2]) -> 314058 | E36: =MIN(Table145678910234111213[No. Of Iterations Block Of Text - Run 3]) -> 283908 | F36: =MIN(Table145678910234111213[No. Of Iterations Block Of Text - Run 4]) -> 325675 | G36: =MIN(Table145678910234111213[No. Of Iterations Block Of Text - Run 5]) -> 310634 | H36: =MIN(Table145678910234111213[No. Of Iterations Block Of Text - Run 6]) -> 327544 | I36: =MIN(Table145678910234111213[No. Of Iterations Block Of Text - Run 7]) -> 287918 | J36: =MIN(Table145678910234111213[No. Of Iterations Block Of Text - Run 8]) -> 316965 | K36: =MIN(Table145678910234111213[No. Of Iterations Block Of Text - Run 9]) -> 282415 | L36: =MIN(Table145678910234111213[No. Of Iterations Block Of Text - Run 10]) -> 322104
A37: Max No. Of Iterations | C37: =MAX(Table145678910234111213[No. Of Iterations Block Of Text - Run 1]) -> 385768 | D37: =MAX(Table145678910234111213[No. Of Iterations Block Of Text - Run 2]) -> 388675 | E37: =MAX(Table145678910234111213[No. Of Iterations Block Of Text - Run 3]) -> 390909 | F37: =MAX(Table145678910234111213[No. Of Iterations Block Of Text - Run 4]) -> 389873 | G37: =MAX(Table145678910234111213[No. Of Iterations Block Of Text - Run 5]) -> 384460 | H37: =MAX(Table145678910234111213[No. Of Iterations Block Of Text - Run 6]) -> 381199 | I37: =MAX(Table145678910234111213[No. Of Iterations Block Of Text - Run 7]) -> 372895 | J37: =MAX(Table145678910234111213[No. Of Iterations Block Of Text - Run 8]) -> 379764 | K37: =MAX(Table145678910234111213[No. Of Iterations Block Of Text - Run 9]) -> 384589 | L37: =MAX(Table145678910234111213[No. Of Iterations Block Of Text - Run 10]) -> 381612
A38: Range (Max - Min) | C38: =C37-C36 -> 77671 | D38: =D37-D36 -> 74617 | E38: =E37-E36 -> 107001 | F38: =F37-F36 -> 64198 | G38: =G37-G36 -> 73826 | H38: =H37-H36 -> 53655 | I38: =I37-I36 -> 84977 | J38: =J37-J36 -> 62799 | ... L38: =L37-L36 -> 59508
A39: Range (percentage of Min) | C39: =C38/C36 -> 0.25209918 | D39: =D38/D36 -> 0.23758987 | E39: =E38/E36 -> 0.37688617 | F39: =F38/F36 -> 0.1971229 | G39: =G38/G36 -> 0.23766233 | H39: =H38/H36 -> 0.16381005 | I39: =I38/I36 -> 0.29514306 | J39: =J38/J36 -> 0.19812598 | ... L39: =L38/L36 -> 0.18474778
A40: Smallest Range (Tightest Execution) (%) | C40: =MIN(C39:L39) -> 0.16381005
A41: Largest Range (Loosest Execution) (%) | C41: =MAX(C39:L39) -> 0.37688617
...

Sheet Exp13
B1: Experiment 13.vi with subroutine VIs (DDS "Case 1: Subroutines")
B2: No. | C2: No. Of Iterations Block Of Text - Run 1 | D2: No. Of Iterations Block Of Text - Run 2 | E2: No. Of Iterations Block Of Text - Run 3 | F2: No. Of Iterations Block Of Text - Run 4 | G2: No. Of Iterations Block Of Text - Run 5 | H2: No. Of Iterations Block Of Text - Run 6 | I2: No. Of Iterations Block Of Text - Run 7 | J2: No. Of Iterations Block Of Text - Run 8 | K2: No. Of Iterations Block Of Text - Run 9 | L2: No. Of Iterations Block Of Text - Run 10
B3: 1 | C3: 524242 | D3: 518321 | E3: 521272 | F3: 519023 | G3: 519462 | H3: 525795 | I3: 526209 | J3: 511149 | K3: 503591 | L3: 532234
B4: 2 | C4: 534469 | D4: 519558 | E4: 525659 | F4: 514189 | G4: 529572 | H4: 527506 | I4: 521384 | J4: 520775 | K4: 537787 | L4: 526196
B5: 3 | C5: 516906 | D5: 534085 | E5: 535203 | F5: 529521 | G5: 532209 | H5: 525251 | I5: 526820 | J5: 514997 | K5: 541155 | L5: 526993
B6: 4 | C6: 514581 | D6: 535467 | E6: 519300 | F6: 511111 | G6: 524093 | H6: 524537 | I6: 522246 | J6: 512508 | K6: 500735 | L6: 523771
A7: Avg No. Of Iterations | C7: =AVERAGE(Table145678910234111214[No. Of Iterations Block Of Text - Run 1]) -> 522549.5 | D7: =AVERAGE(Table145678910234111214[No. Of Iterations Block Of Text - Run 2]) -> 526857.75 | E7: =AVERAGE(Table145678910234111214[No. Of Iterations Block Of Text - Run 3]) -> 525358.5 | F7: =AVERAGE(Table145678910234111214[No. Of Iterations Block Of Text - Run 4]) -> 518461 | G7: =AVERAGE(Table145678910234111214[No. Of Iterations Block Of Text - Run 5]) -> 526334 | H7: =AVERAGE(Table145678910234111214[No. Of Iterations Block Of Text - Run 6]) -> 525772.25 | I7: =AVERAGE(Table145678910234111214[No. Of Iterations Block Of Text - Run 7]) -> 524164.75 | J7: =AVERAGE(Table145678910234111214[No. Of Iterations Block Of Text - Run 8]) -> 514857.25 | K7: =AVERAGE(Table145678910234111214[No. Of Iterations Block Of Text - Run 9]) -> 520817 | L7: =AVERAGE(Table145678910234111214[No. Of Iterations Block Of Text - Run 10]) -> 527298.5
A8: Min No. Of Iterations | C8: =MIN(Table145678910234111214[No. Of Iterations Block Of Text - Run 1]) -> 514581 | D8: =MIN(Table145678910234111214[No. Of Iterations Block Of Text - Run 2]) -> 518321 | E8: =MIN(Table145678910234111214[No. Of Iterations Block Of Text - Run 3]) -> 519300 | F8: =MIN(Table145678910234111214[No. Of Iterations Block Of Text - Run 4]) -> 511111 | G8: =MIN(Table145678910234111214[No. Of Iterations Block Of Text - Run 5]) -> 519462 | H8: =MIN(Table145678910234111214[No. Of Iterations Block Of Text - Run 6]) -> 524537 | I8: =MIN(Table145678910234111214[No. Of Iterations Block Of Text - Run 7]) -> 521384 | J8: =MIN(Table145678910234111214[No. Of Iterations Block Of Text - Run 8]) -> 511149 | K8: =MIN(Table145678910234111214[No. Of Iterations Block Of Text - Run 9]) -> 500735 | L8: =MIN(Table145678910234111214[No. Of Iterations Block Of Text - Run 10]) -> 523771
A9: Max No. Of Iterations | C9: =MAX(Table145678910234111214[No. Of Iterations Block Of Text - Run 1]) -> 534469 | D9: =MAX(Table145678910234111214[No. Of Iterations Block Of Text - Run 2]) -> 535467 | E9: =MAX(Table145678910234111214[No. Of Iterations Block Of Text - Run 3]) -> 535203 | F9: =MAX(Table145678910234111214[No. Of Iterations Block Of Text - Run 4]) -> 529521 | G9: =MAX(Table145678910234111214[No. Of Iterations Block Of Text - Run 5]) -> 532209 | H9: =MAX(Table145678910234111214[No. Of Iterations Block Of Text - Run 6]) -> 527506 | I9: =MAX(Table145678910234111214[No. Of Iterations Block Of Text - Run 7]) -> 526820 | J9: =MAX(Table145678910234111214[No. Of Iterations Block Of Text - Run 8]) -> 520775 | K9: =MAX(Table145678910234111214[No. Of Iterations Block Of Text - Run 9]) -> 541155 | L9: =MAX(Table145678910234111214[No. Of Iterations Block Of Text - Run 10]) -> 532234
A10: Range (Max - Min) | C10: =C9-C8 -> 19888 | D10: =D9-D8 -> 17146 | E10: =E9-E8 -> 15903 | F10: =F9-F8 -> 18410 | G10: =G9-G8 -> 12747 | H10: =H9-H8 -> 2969 | I10: =I9-I8 -> 5436 | J10: =J9-J8 -> 9626 | ... L10: =L9-L8 -> 8463
A11: Range (percentage of Min) | C11: =C10/C8 -> 0.03864892 | D11: =D10/D8 -> 0.033079887 | E11: =E10/E8 -> 0.030623917 | F11: =F10/F8 -> 0.036019573 | G11: =G10/G8 -> 0.02453885 | H11: =H10/H8 -> 0.0056602299 | I11: =I10/I8 -> 0.010426097 | J11: =J10/J8 -> 0.018832082 | ... L11: =L10/L8 -> 0.016157825
A12: Smallest Range (Tightest Execution) (%) | C12: =MIN(C11:L11) -> 0.0056602299
A13: Largest Range (Loosest Execution) (%) | C13: =MAX(C11:L11) -> 0.08072134
A14: Average Range (%) | C14: =AVERAGE(C11:L11) -> 0.029470872
A15: Overall Average No. Of Iterations | C15: =AVERAGE(C7:L7) -> 523247.05
B17: Experiment 13.vi with inline VIs (DDS "Case 2: Inline VIs")
B18: No. | C18: No. Of Iterations Block Of Text - Run 1 | D18: No. Of Iterations Block Of Text - Run 2 | E18: No. Of Iterations Block Of Text - Run 3 | F18: No. Of Iterations Block Of Text - Run 4 | G18: No. Of Iterations Block Of Text - Run 5 | H18: No. Of Iterations Block Of Text - Run 6 | I18: No. Of Iterations Block Of Text - Run 7 | J18: No. Of Iterations Block Of Text - Run 8 | K18: No. Of Iterations Block Of Text - Run 9 | L18: No. Of Iterations Block Of Text - Run 10
B19: 1 | C19: 555645 | D19: 560051 | E19: 557377 | F19: 539593 | G19: 551734 | H19: 538105 | I19: 540211 | J19: 564497 | K19: 555785 | L19: 546741
B20: 2 | C20: 561279 | D20: 557112 | E20: 550891 | F20: 556436 | G20: 552803 | H20: 564887 | I20: 576429 | J20: 564362 | K20: 552398 | L20: 554431
B21: 3 | C21: 546441 | D21: 569611 | E21: 559068 | F21: 561380 | G21: 556153 | H21: 564765 | I21: 571210 | J21: 559730 | K21: 550105 | L21: 546461
B22: 4 | C22: 548978 | D22: 559142 | E22: 553974 | F22: 547269 | G22: 557372 | H22: 551041 | I22: 545637 | J22: 555855 | K22: 555896 | L22: 552149
A23: Avg No. Of Iterations | C23: =AVERAGE(Table14567891023411121315[No. Of Iterations Block Of Text - Run 1]) -> 553085.75 | D23: =AVERAGE(Table14567891023411121315[No. Of Iterations Block Of Text - Run 2]) -> 561479 | E23: =AVERAGE(Table14567891023411121315[No. Of Iterations Block Of Text - Run 3]) -> 555327.5 | F23: =AVERAGE(Table14567891023411121315[No. Of Iterations Block Of Text - Run 4]) -> 551169.5 | G23: =AVERAGE(Table14567891023411121315[No. Of Iterations Block Of Text - Run 5]) -> 554515.5 | H23: =AVERAGE(Table14567891023411121315[No. Of Iterations Block Of Text - Run 6]) -> 554699.5 | I23: =AVERAGE(Table14567891023411121315[No. Of Iterations Block Of Text - Run 7]) -> 558371.75 | J23: =AVERAGE(Table14567891023411121315[No. Of Iterations Block Of Text - Run 8]) -> 561111 | K23: =AVERAGE(Table14567891023411121315[No. Of Iterations Block Of Text - Run 9]) -> 553546 | L23: =AVERAGE(Table14567891023411121315[No. Of Iterations Block Of Text - Run 10]) -> 549945.5
A24: Min No. Of Iterations | C24: =MIN(Table14567891023411121315[No. Of Iterations Block Of Text - Run 1]) -> 546441 | D24: =MIN(Table14567891023411121315[No. Of Iterations Block Of Text - Run 2]) -> 557112 | E24: =MIN(Table14567891023411121315[No. Of Iterations Block Of Text - Run 3]) -> 550891 | F24: =MIN(Table14567891023411121315[No. Of Iterations Block Of Text - Run 4]) -> 539593 | G24: =MIN(Table14567891023411121315[No. Of Iterations Block Of Text - Run 5]) -> 551734 | H24: =MIN(Table14567891023411121315[No. Of Iterations Block Of Text - Run 6]) -> 538105 | I24: =MIN(Table14567891023411121315[No. Of Iterations Block Of Text - Run 7]) -> 540211 | J24: =MIN(Table14567891023411121315[No. Of Iterations Block Of Text - Run 8]) -> 555855 | K24: =MIN(Table14567891023411121315[No. Of Iterations Block Of Text - Run 9]) -> 550105 | L24: =MIN(Table14567891023411121315[No. Of Iterations Block Of Text - Run 10]) -> 546461
A25: Max No. Of Iterations | C25: =MAX(Table14567891023411121315[No. Of Iterations Block Of Text - Run 1]) -> 561279 | D25: =MAX(Table14567891023411121315[No. Of Iterations Block Of Text - Run 2]) -> 569611 | E25: =MAX(Table14567891023411121315[No. Of Iterations Block Of Text - Run 3]) -> 559068 | F25: =MAX(Table14567891023411121315[No. Of Iterations Block Of Text - Run 4]) -> 561380 | G25: =MAX(Table14567891023411121315[No. Of Iterations Block Of Text - Run 5]) -> 557372 | H25: =MAX(Table14567891023411121315[No. Of Iterations Block Of Text - Run 6]) -> 564887 | I25: =MAX(Table14567891023411121315[No. Of Iterations Block Of Text - Run 7]) -> 576429 | J25: =MAX(Table14567891023411121315[No. Of Iterations Block Of Text - Run 8]) -> 564497 | K25: =MAX(Table14567891023411121315[No. Of Iterations Block Of Text - Run 9]) -> 555896 | L25: =MAX(Table14567891023411121315[No. Of Iterations Block Of Text - Run 10]) -> 554431
A26: Range (Max - Min) | C26: =C25-C24 -> 14838 | D26: =D25-D24 -> 12499 | E26: =E25-E24 -> 8177 | F26: =F25-F24 -> 21787 | G26: =G25-G24 -> 5638 | H26: =H25-H24 -> 26782 | I26: =I25-I24 -> 36218 | J26: =J25-J24 -> 8642 | ... L26: =L25-L24 -> 7970
A27: Range (percentage of Min) | C27: =C26/C24 -> 0.027153892 | D27: =D26/D24 -> 0.022435345 | E27: =E26/E24 -> 0.014843227 | F27: =F26/F24 -> 0.040376728 | G27: =G26/G24 -> 0.010218692 | H27: =H26/H24 -> 0.049770955 | I27: =I26/I24 -> 0.067044173 | J27: =J26/J24 -> 0.01554722 | ... L27: =L26/L24 -> 0.014584755
A28: Smallest Range (Tightest Execution) (%) | C28: =MIN(C27:L27) -> 0.010218692
A29: Largest Range (Loosest Execution) (%) | C29: =MAX(C27:L27) -> 0.067044173
A30: Average Range (%) | C30: =AVERAGE(C27:L27) -> 0.027250207
A31: Overall Average No. Of Iterations | C31: =AVERAGE(C23:L23) -> 555325.1

Sheet Exp14
B1: Experiment 14.vi with subroutine VIs (DDS "Case 1: Subroutines")
B2: No. | C2: No. Of Iterations Block Of Text - Run 1 | D2: No. Of Iterations Block Of Text - Run 2 | E2: No. Of Iterations Block Of Text - Run 3 | F2: No. Of Iterations Block Of Text - Run 4 | G2: No. Of Iterations Block Of Text - Run 5 | H2: No. Of Iterations Block Of Text - Run 6 | I2: No. Of Iterations Block Of Text - Run 7 | J2: No. Of Iterations Block Of Text - Run 8 | K2: No. Of Iterations Block Of Text - Run 9 | L2: No. Of Iterations Block Of Text - Run 10
B3: 1 | C3: 562157 | D3: 556343 | E3: 542911 | F3: 548845 | G3: 562603 | H3: 547132 | I3: 561879 | J3: 560312 | K3: 547556 | L3: 543133
B4: 2 | C4: 562906 | D4: 554854 | E4: 543743 | F4: 547698 | G4: 563371 | H4: 546198 | I4: 560859 | J4: 560955 | K4: 548612 | L4: 542993
A5: Avg No. Of Iterations | C5: =AVERAGE(Table14567891023411121416[No. Of Iterations Block Of Text - Run 1]) -> 562531.5 | D5: =AVERAGE(Table14567891023411121416[No. Of Iterations Block Of Text - Run 2]) -> 555598.5 | E5: =AVERAGE(Table14567891023411121416[No. Of Iterations Block Of Text - Run 3]) -> 543327 | F5: =AVERAGE(Table14567891023411121416[No. Of Iterations Block Of Text - Run 4]) -> 548271.5 | G5: =AVERAGE(Table14567891023411121416[No. Of Iterations Block Of Text - Run 5]) -> 562987 | H5: =AVERAGE(Table14567891023411121416[No. Of Iterations Block Of Text - Run 6]) -> 546665 | I5: =AVERAGE(Table14567891023411121416[No. Of Iterations Block Of Text - Run 7]) -> 561369 | J5: =AVERAGE(Table14567891023411121416[No. Of Iterations Block Of Text - Run 8]) -> 560633.5 | K5: =AVERAGE(Table14567891023411121416[No. Of Iterations Block Of Text - Run 9]) -> 548084 | L5: =AVERAGE(Table14567891023411121416[No. Of Iterations Block Of Text - Run 10]) -> 543063
A6: Min No. Of Iterations | C6: =MIN(Table14567891023411121416[No. Of Iterations Block Of Text - Run 1]) -> 562157 | D6: =MIN(Table14567891023411121416[No. Of Iterations Block Of Text - Run 2]) -> 554854 | E6: =MIN(Table14567891023411121416[No. Of Iterations Block Of Text - Run 3]) -> 542911 | F6: =MIN(Table14567891023411121416[No. Of Iterations Block Of Text - Run 4]) -> 547698 | G6: =MIN(Table14567891023411121416[No. Of Iterations Block Of Text - Run 5]) -> 562603 | H6: =MIN(Table14567891023411121416[No. Of Iterations Block Of Text - Run 6]) -> 546198 | I6: =MIN(Table14567891023411121416[No. Of Iterations Block Of Text - Run 7]) -> 560859 | J6: =MIN(Table14567891023411121416[No. Of Iterations Block Of Text - Run 8]) -> 560312 | K6: =MIN(Table14567891023411121416[No. Of Iterations Block Of Text - Run 9]) -> 547556 | L6: =MIN(Table14567891023411121416[No. Of Iterations Block Of Text - Run 10]) -> 542993
A7: Max No. Of Iterations | C7: =MAX(Table14567891023411121416[No. Of Iterations Block Of Text - Run 1]) -> 562906 | D7: =MAX(Table14567891023411121416[No. Of Iterations Block Of Text - Run 2]) -> 556343 | E7: =MAX(Table14567891023411121416[No. Of Iterations Block Of Text - Run 3]) -> 543743 | F7: =MAX(Table14567891023411121416[No. Of Iterations Block Of Text - Run 4]) -> 548845 | G7: =MAX(Table14567891023411121416[No. Of Iterations Block Of Text - Run 5]) -> 563371 | H7: =MAX(Table14567891023411121416[No. Of Iterations Block Of Text - Run 6]) -> 547132 | I7: =MAX(Table14567891023411121416[No. Of Iterations Block Of Text - Run 7]) -> 561879 | J7: =MAX(Table14567891023411121416[No. Of Iterations Block Of Text - Run 8]) -> 560955 | K7: =MAX(Table14567891023411121416[No. Of Iterations Block Of Text - Run 9]) -> 548612 | L7: =MAX(Table14567891023411121416[No. Of Iterations Block Of Text - Run 10]) -> 543133
A8: Range (Max - Min) | C8: =C7-C6 -> 749 | D8: =D7-D6 -> 1489 | E8: =E7-E6 -> 832 | F8: =F7-F6 -> 1147 | G8: =G7-G6 -> 768 | H8: =H7-H6 -> 934 | I8: =I7-I6 -> 1020 | J8: =J7-J6 -> 643 | ... L8: =L7-L6 -> 140
A9: Range (percentage of Min) | C9: =C8/C6 -> 0.001332368 | D9: =D8/D6 -> 0.0026835888 | E9: =E8/E6 -> 0.0015324795 | F9: =F8/F6 -> 0.0020942198 | G9: =G8/G6 -> 0.0013650834 | H9: =H8/H6 -> 0.0017100026 | I9: =I8/I6 -> 0.0018186389 | J9: =J8/J6 -> 0.0011475749 | ... L9: =L8/L6 -> 0.00025783021
A10: Smallest Range (Tightest Execution) (%) | C10: =MIN(C9:L9) -> 0.00025783021
A11: Largest Range (Loosest Execution) (%) | C11: =MAX(C9:L9) -> 0.0026835888
A12: Average Range (%) | C12: =AVERAGE(C9:L9) -> 0.0015870356
A13: Overall Average No. Of Iterations | C13: =AVERAGE(C5:L5) -> 553253
B15: Experiment 14.vi with inline VIs (DDS "Case 2: Inline VIs")
B16: No. | C16: No. Of Iterations Block Of Text - Run 1 | D16: No. Of Iterations Block Of Text - Run 2 | E16: No. Of Iterations Block Of Text - Run 3 | F16: No. Of Iterations Block Of Text - Run 4 | G16: No. Of Iterations Block Of Text - Run 5 | H16: No. Of Iterations Block Of Text - Run 6 | I16: No. Of Iterations Block Of Text - Run 7 | J16: No. Of Iterations Block Of Text - Run 8 | K16: No. Of Iterations Block Of Text - Run 9 | L16: No. Of Iterations Block Of Text - Run 10
B17: 1 | C17: 606067 | D17: 592625 | E17: 596002 | F17: 601597 | G17: 605906 | H17: 606069 | I17: 596723 | J17: 581068 | K17: 602175 | L17: 606850
B18: 2 | C18: 604263 | D18: 593189 | E18: 593468 | F18: 600859 | G18: 604983 | H18: 604973 | I18: 597276 | J18: 579890 | K18: 600119 | L18: 606724
A19: Avg No. Of Iterations | C19: =AVERAGE(Table1456789102341112131517[No. Of Iterations Block Of Text - Run 1]) -> 605165 | D19: =AVERAGE(Table1456789102341112131517[No. Of Iterations Block Of Text - Run 2]) -> 592907 | E19: =AVERAGE(Table1456789102341112131517[No. Of Iterations Block Of Text - Run 3]) -> 594735 | F19: =AVERAGE(Table1456789102341112131517[No. Of Iterations Block Of Text - Run 4]) -> 601228 | G19: =AVERAGE(Table1456789102341112131517[No. Of Iterations Block Of Text - Run 5]) -> 605444.5 | H19: =AVERAGE(Table1456789102341112131517[No. Of Iterations Block Of Text - Run 6]) -> 605521 | I19: =AVERAGE(Table1456789102341112131517[No. Of Iterations Block Of Text - Run 7]) -> 596999.5 | J19: =AVERAGE(Table1456789102341112131517[No. Of Iterations Block Of Text - Run 8]) -> 580479 | K19: =AVERAGE(Table1456789102341112131517[No. Of Iterations Block Of Text - Run 9]) -> 601147 | L19: =AVERAGE(Table1456789102341112131517[No. Of Iterations Block Of Text - Run 10]) -> 606787
A20: Min No. Of Iterations | C20: =MIN(Table1456789102341112131517[No. Of Iterations Block Of Text - Run 1]) -> 604263 | D20: =MIN(Table1456789102341112131517[No. Of Iterations Block Of Text - Run 2]) -> 592625 | E20: =MIN(Table1456789102341112131517[No. Of Iterations Block Of Text - Run 3]) -> 593468 | F20: =MIN(Table1456789102341112131517[No. Of Iterations Block Of Text - Run 4]) -> 600859 | G20: =MIN(Table1456789102341112131517[No. Of Iterations Block Of Text - Run 5]) -> 604983 | H20: =MIN(Table1456789102341112131517[No. Of Iterations Block Of Text - Run 6]) -> 604973 | I20: =MIN(Table1456789102341112131517[No. Of Iterations Block Of Text - Run 7]) -> 596723 | J20: =MIN(Table1456789102341112131517[No. Of Iterations Block Of Text - Run 8]) -> 579890 | K20: =MIN(Table1456789102341112131517[No. Of Iterations Block Of Text - Run 9]) -> 600119 | L20: =MIN(Table1456789102341112131517[No. Of Iterations Block Of Text - Run 10]) -> 606724
